<?xml version="1.0"?>
<robot xmlns:xacro="http://www.ros.org/wiki/xacro" name="my_robot">


  <link name="base_link">
    <visual>
      <geometry>
        <box size="0.5 0.3 0.2"/>
      </geometry>
      <material name="blue">
        <color rgba="0.5 0.5 1.0 1.0"/>
      </material>
    </visual>
  </link>

  <link name="wheel_link">
    <visual>
      <geometry>
        <cylinder radius="0.1" length="0.05"/>
      </geometry>
      <origin xyz="0 0 0" rpy="1.58 0 0"/>
      <material name="black">
        <color rgba="0.8 0.6 0.1 1.0"/>
      </material>
    </visual>
  </link>

  <joint name="wheel_joint" type="continuous">
    <parent link="base_link"/>
    <child link="wheel_link"/>
    <origin xyz="0.2 0 -0.1" rpy="0 0 0"/>
    <axis xyz="0 1 0"/>
  </joint>


</robot>